1. 没有异常机制
2. error类型实现error接口
```go
type error interface{
	Error() string
}
//一般这样定义一个error
```
3. 可以通过errors.New快速创建错误实例
```go
errors.New("n must be in ...")
```

**提前犯错大于事后弥补**

```go
var SmallerThanZeroError = errors.New("数字应当大于0")
var LagerThanTenError = errors.New("数字应当小于10")
func NumberBetween(num int) (int,error){
	switch {
	case 0>num:return num,SmallerThanZeroError
	case 0<=num && num<=10: return num,nil
	case 10<num: return num,LagerThanTenError
	}
	return num, nil
}

func TestError(t *testing.T){
	var (
		i int
		err error
	)
	if i , err=NumberBetween(59);err!=nil{
		fmt.Print("Error", err)
		return
	}
	fmt.Print(i)
}
```

## panic与recover
1. panic用于不可恢复的错误
2. panic退出前会执行defer.而os.Exit退出时不会调用defer指定的函数,也不会输出当前调用栈信息

- panic接收的是一个空接口,一般传入错误

- recover()用在defer中,可以接收panic中传入的错误.来进行一个错误的恢复
```go
func TestPanic(t *testing.T){
	defer func(){
		if err := recover();err != nil{
			fmt.Print("recovered from", err)
		}
	}()
	fmt.Print("Start")
	panic(errors.New("something wrong"))
}
```
**这个地方只是将错误信息打印日志.而没有真的处理错误,可能会导致僵尸进程**
**有时候不如cash错误,通过守护进程重启服务进程**

